Workbook
Name _Hlk127452852: Gajendra!$L$8
Name _Hlk133227457: Yogesh!$I$86
Name _Hlk147505528: Yogesh!$L$61

Sheet Summary
B1: KARDEX LCS : LIVE OFFER FUNNEL,ACTUALS, DEVIATIONS - 2025 | S1: =((T1*94)/12)*1000 -> 23515667 | T1: 3002 | U1: =T1/12 -> 250.16667
B3: Offers Highlights | Q3: Forecast | S3: WEST | T3: SOUTH | U3: NORTH | V3: EAST
Q4: January | R4: =SUM(S4:V4) -> 45050692 | S4: =SUM(Yogesh!AE3+Ashraf!AE3+Rahul!AE3+Minesh!AE3) -> 15096544 | T4: =SUM(Gajendra!AF5+Pradeep!AF4+Sasi!AF4) -> 16046921 | U4: =SUM(Vinay!AF3+Nitin!AD4) -> 13078516 | V4: =Pankaj!AF3 -> 828711 | AA4: From Day 1 of each Month
B5: Zone | C5: No. of Offers | D5: Offers Value | E5: Orders Received | F5: Open Funnel | G5: Order Booking | H5: BU for Booking /2025 | I5: % | J5: Balance BU | Q5: February | R5: =SUM(S5:V5) -> 21122869 | S5: =SUM(Yogesh!AE4+Ashraf!AE4+Rahul!AE4+Minesh!AE4) -> 7548651 | T5: =SUM(Gajendra!AF6+Pradeep!AF5+Sasi!AF5) -> 6939439.8 | U5: =SUM(Vinay!AF4+Nitin!AD5) -> 6400898 | V5: =Pankaj!AF4 -> 233880 | W5: Q1 Forecast | X5: Q1 BU | Y5: Dev | AA5: Month | AB5: Forecast | AC5: Euro | AD5: Start of the Month | AE5: WEST | AF5: SOUTH | AG5: NORTH | AH5: EAST
B6: WEST | C6: =Yogesh!B4+Ashraf!B5+Minesh!B4+Rahul!B4 -> 529 | D6: =C28 -> 201107949 | E6: =D28 -> 132310920 | F6: =Yogesh!V5+Ashraf!V6+Rahul!V5+Minesh!V5 -> 47022033 | G6: =E28 -> 128881401 | H6: 121446000 | I6: =(H6-G6)/-H6 -> 0.061223927 | J6: =H6-G6 -> -7435401 | Q6: March | R6: =SUM(S6:V6) -> 24059432 | S6: =SUM(Yogesh!AE5+Ashraf!AE5+Rahul!AE5+Minesh!AE5) -> 10061774 | T6: =SUM(Gajendra!AF7+Pradeep!AF6+Sasi!AF6) -> 10184994 | U6: =SUM(Vinay!AF5+Nitin!AD6) -> 2708802 | V6: =Pankaj!AF5 -> 1103862 | W6: =SUM(R4:R6) -> 90232993 | X6: =S1*3 -> 70547000 | Y6: =SUM(W6-X6)/X6 -> 0.27904791 | AA6: FEB | AB6: =SUM(AE6:AH6) -> 39877565 | AC6: =(AB6/$S$97)/1000 -> 428.79102 | AD6: Febrauary | AE6: 9286760 | AF6: 12347508 | AG6: 17539857 | AH6: 703440
B7: SOUTH | C7: =Gajendra!B5+Pradeep!B4+Sasi!B4 -> 354 | D7: =C45 -> 1.7686402e+08 | E7: =D45 -> 95676327 | F7: =Gajendra!V6+Pradeep!V5+Sasi!V5 -> 63631579 | G7: =E45 -> 100601530 | H7: 107487000 | I7: =(H7-G7)/-H7 -> -0.06405863 | J7: =H7-G7 -> 6885470 | Q7: April | R7: =SUM(S7:V7) -> 61495167 | S7: =SUM(Yogesh!AE6+Ashraf!AE6+Rahul!AE6+Minesh!AE6) -> 38455613 | T7: =SUM(Gajendra!AF8+Pradeep!AF7+Sasi!AF7) -> 13886379 | U7: =SUM(Vinay!AF6+Nitin!AD7) -> 9153175 | V7: =Pankaj!AF6 -> 0 | AA7: MAR | AB7: =SUM(AE7:AH7) -> 24653350 | AC7: =(AB7/$S$97)/1000 -> 265.08979 | AD7: March | AE7: 8359399 | AF7: 15286310 | AG7: 1007641 | AH7: 0
B8: NORTH | C8: =Nitin!B4+Vinay!B4 -> 172 | D8: =C62 -> 101408542 | E8: =D62 -> 25743743 | F8: =Vinay!V5+Nitin!V5 -> 43216777 | G8: =E62 -> 31713749 | H8: 39086000 | I8: =(H8-G8)/-H8 -> -0.18861615 | J8: =H8-G8 -> 7372251 | Q8: May | R8: =SUM(S8:V8) -> 26287547 | S8: =SUM(Yogesh!AE7+Ashraf!AE7+Rahul!AE7+Minesh!AE7) -> 15750042 | T8: =SUM(Gajendra!AF9+Pradeep!AF8+Sasi!AF8) -> 4930834.8 | U8: =Vinay!AF7+Nitin!AF8 -> 4567340 | V8: =Pankaj!AF7 -> 1039330 | W8: Q2 Forecast | X8: Q2 BU | Y8: Dev | AA8: APR | AB8: =SUM(AE8:AH8) -> 53554063 | AC8: =(AB8/$S$97)/1000 -> 575.85014 | AD8: April | AE8: 35536379 | AF8: 16382704 | AG8: 1634980 | AH8: 0
B9: EAST | C9: =Pankaj!B4 -> 29 | D9: =C79 -> 12643664 | E9: =D79 -> 4782292.4 | F9: =Pankaj!V5 -> 7778194.6 | G9: =E79 -> 5968893 | H9: 11167000 | I9: =(H9-G9)/-H9 -> -0.46548822 | J9: =H9-G9 -> 5198107 | Q9: June | R9: =SUM(S9:V9) -> 25930489 | S9: =SUM(Yogesh!AE8+Ashraf!AE8+Rahul!AE8+Minesh!AE8) -> 16934646 | T9: =SUM(Gajendra!AF10+Pradeep!AF9+Sasi!AF9) -> 3121332 | U9: =SUM(Vinay!AF8+Nitin!AF9) -> 5874511 | V9: =Pankaj!AF8 -> 0 | W9: =SUM(R7:R9) -> 1.137132e+08 | X9: =S1*3 -> 70547000 | Y9: =SUM(W9-X9)/X9 -> 0.61187864 | AA9: MAY | AB9: =SUM(AE9:AH9) -> 45486916 | AC9: =(AB9/$S$97)/1000 -> 489.10662 | AD9: May | AE9: 27968195 | AF9: 9505075.8 | AG9: 6429763 | AH9: 1583882
B10: Total | C10: =SUM(C6:C9) -> 1084 | D10: =SUM(D6:D9) -> 4.9202418e+08 | E10: =SUM(E6:E9) -> 2.5851328e+08 | F10: =SUM(F6:F9) -> 1.6164858e+08 | G10: =SUM(G6:G9) -> 267165573 | H10: =SUM(H6:H9) -> 279186000 | I10: =(H10-G10)/-H10 -> -0.043055264 | J10: =H10-G10 -> 12020427 | Q10: July | R10: =SUM(S10:V10) -> 25780849 | S10: =SUM(Yogesh!AE9+Ashraf!AE9+Rahul!AE9+Minesh!AE9) -> 8768673 | T10: =SUM(Gajendra!AF11+Pradeep!AF10+Sasi!AF10) -> 14634990 | U10: =SUM(Vinay!AD12+Nitin!AD10) -> 1972332 | V10: =Pankaj!AF9 -> 404854 | AA10: JUN | AB10: =SUM(AE10:AH10) -> 37217079 | AC10: =(AB10/$S$97)/1000 -> 400.18365 | AD10: June | AE10: 24125701 | AF10: 11748673 | AG10: 1203007 | AH10: 139698
Q11: August | R11: =SUM(S11:V11) -> 38786728 | S11: =SUM(Yogesh!AE10+Ashraf!AE10+Rahul!AE10+Minesh!AE10) -> 13636734 | T11: =SUM(Gajendra!AF12+Pradeep!AF11+Sasi!AF11) -> 19450949 | U11: =SUM(Vinay!AF10+Nitin!AD11) -> 5538869 | V11: =Pankaj!AF10 -> 160176 | W11: Q3 Forecast | X11: Q3 BU | Y11: Dev | AA11: JULY | AB11: =SUM(AE11:AH11) -> 23876033 | AC11: =(AB11/$S$97)/1000 -> 256.73154 | AD11: July | AE11: 8954264 | AF11: 14251915 | AG11: 265000 | AH11: 404854
B12: NOTE : * Marked fields will be filled by Girija | Q12: September | R12: =SUM(S12:V12) -> 35015662 | S12: =SUM(Yogesh!AE11+Ashraf!AE11+Rahul!AE11+Minesh!AE11) -> 9602168 | T12: =SUM(Gajendra!AF13+Pradeep!AF12+Sasi!AF12) -> 16361962 | U12: =SUM(Vinay!AF10+Nitin!AD12) -> 8870957 | V12: =Pankaj!AF11 -> 180576 | W12: =SUM(R10:R12) -> 99583240 | X12: =S1*3 -> 70547000 | Y12: =SUM(W12-X12)/X12 -> 0.41158717 | AA12: AUG | AB12: =SUM(AE12:AH12) -> 48070994 | AC12: =(AB12/$S$97)/1000 -> 516.89241 | AD12: August | AE12: 20686301 | AF12: 25365441 | AG12: 1879554 | AH12: 139698
H13: 121446000 | K13: HIT RATE | L13: =D28/C28 -> 0.65790995 | Q13: October | R13: =SUM(S13:V13) -> 34898550 | S13: =SUM(Yogesh!AE12+Ashraf!AE12+Rahul!AE12+Minesh!AE12) -> 9102357 | T13: =SUM(Gajendra!AF14+Pradeep!AF13+Sasi!AF13) -> 16463774 | U13: =SUM(Vinay!AF11+Nitin!AD13) -> 8462431 | V13: =Pankaj!AF12 -> 869988 | AA13: Sept | AB13: =SUM(AE13:AH13) -> 0 | AC13: =(AB13/$S$97)/1000 -> 0 | AD13: September
B14: WEST | Q14: November | R14: =SUM(S14:V14) -> 45443423 | S14: =SUM(Yogesh!AE13+Ashraf!AE13+Rahul!AE13+Minesh!AE13) -> 18982678 | T14: =SUM(Gajendra!AF15+Pradeep!AF14+Sasi!AF14) -> 20007016 | U14: =SUM(Vinay!AF12+Nitin!AD14) -> 3245053 | V14: =Pankaj!AF13 -> 3208676 | W14: Q4 Forecast | X14: Q4 BU | Y14: Dev | AA14: Oct | AB14: =SUM(AE14:AH14) -> 0 | AC14: =(AB14/$S$97)/1000 -> 0 | AD14: October
B15: Month | C15: Offers/Value | D15: Order Received | E15: *Orders Booked | F15: Dev OR vs Booked | G15: *Orders In-Hand | H15: BU/Monthly | I15: Booked vs BU | J15: % Dev | K15: Offer BU Monthly | L15: % Dev | Q15: December | R15: =SUM(S15:V15) -> 71156885 | S15: =SUM(Yogesh!AE14+Ashraf!AE14+Rahul!AE14+Minesh!AE14) -> 34836169 | T15: =SUM(Gajendra!AF16+Pradeep!AF15+Sasi!AF15) -> 32235999 | U15: =SUM(Vinay!AF13+Nitin!AD15) -> 519444 | V15: =Pankaj!AF14 -> 3565273 | W15: =SUM(R13:R15) -> 1.5149886e+08 | X15: =S1*3 -> 70547000 | Y15: =SUM(W15-X15)/X15 -> 1.1474883 | AA15: Nov | AB15: =SUM(AE15:AH15) -> 0 | AC15: =(AB15/$S$97)/1000 -> 0 | AD15: November
B16: Januray | C16: =Yogesh!AC3+Ashraf!AC3+Rahul!AC3+Minesh!AC3 -> 42269479 | D16: =Yogesh!AD3+Ashraf!AD3+Rahul!AD3+Minesh!AD3 -> 13049548 | E16: 7811608 | F16: =D16-E16 -> 5237940 | H16: =$H$13/12 -> 10120500 | I16: =H16-E16 -> 2308892 | J16: =(E16-H16)/E16 -> -0.29557192 | K16: =H16*4 -> 40482000 | L16: =(K16-C16)/K16 -> -0.044154908 | AA16: Dec | AB16: =SUM(AE16:AH16) -> 0 | AC16: =(AB16/$S$97)/1000 -> 0 | AD16: December
B17: Febraury | C17: =Yogesh!AC4+Ashraf!AC4+Rahul!AC4+Minesh!AC4 -> 14144161 | D17: =Yogesh!AD4+Ashraf!AD4+Rahul!AD4+Minesh!AD4 -> 5515905 | E17: 6378607 | F17: =D17-E17 -> -862702 | G17: 4650252 | H17: =$H$13/12 -> 10120500 | I17: =H17-E17 -> 3741893 | J17: =(E17-H17)/E17 -> -0.58663169 | K17: =H17*4 -> 40482000 | L17: =(K17-C17)/K17 -> 0.65060617 | Q17: Product type | R17: Yogesh | S17: Ashraf | T17: Rahul | U17: Minesh | V17: WEST | X17: Product type | Y17: Total of All Zones
B18: March | C18: =Yogesh!AC5+Ashraf!AC5+Rahul!AC5+Minesh!AC5 -> 36601272 | D18: =Yogesh!AD5+Ashraf!AD5+Rahul!AD5+Minesh!AD5 -> 12619158 | E18: 12737918 | F18: =D18-E18 -> -118760 | G18: 6798827 | H18: =$H$13/12 -> 10120500 | I18: =H18-E18 -> -2617418 | J18: =(E18-H18)/E18 -> 0.2054824 | K18: =H18*4 -> 40482000 | L18: =(K18-C18)/K18 -> 0.09586305 | Q18: Contract | R18: =SUMIF(Yogesh!$J$7:$J$121,"Contract",Yogesh!$N$7:$N$122) -> 6066220 | S18: =SUMIF(Ashraf!$J$7:$J$123,"Contract",Ashraf!$N$7:$N$124) -> 5656160 | T18: =SUMIF(Rahul!$J$7:$J$121,"Contract",Rahul!$N$7:$N$122) -> 6519383 | U18: =SUMIF(Minesh!$J$7:$J$121,"Contract",Minesh!$N$7:$N$122) -> 6337225 | V18: =SUM(R18:U18) -> 24578988 | X18: Contract | Y18: =SUM(R18:X18) -> 49157976
B19: April | C19: =Yogesh!AC6+Ashraf!AC6+Rahul!AC6+Minesh!AC6 -> 9380360 | D19: =Yogesh!AD6+Ashraf!AD6+Rahul!AD6+Minesh!AD6 -> 35250947 | E19: 13101611 | F19: =D19-E19 -> 22149336 | G19: 28944762 | H19: =$H$13/12 -> 10120500 | I19: =H19-E19 -> -2981111 | J19: =(E19-H19)/E19 -> 0.22753774 | K19: =H19*4 -> 40482000 | L19: =(K19-C19)/K19 -> 0.76828319 | Q19: BD Spare | R19: =SUMIF(Yogesh!$J$8:$J$122,"BD Spare",Yogesh!$N$8:S34) -> 532632 | S19: =SUMIF(Ashraf!$J$8:$J$124,"BD Spare",Ashraf!$N$8:T35) -> 401990 | T19: =SUMIF(Rahul!$J$8:$J$122,"BD Spare",Rahul!$N$8:U34) -> 145900 | U19: =SUMIF(Minesh!$J$8:$J$122,"BD Spare",Minesh!$N$8:V34) -> 0 | V19: =SUM(R19:U19) -> 1080522 | X19: BD Spare | Y19: =SUM(R19:X19) -> 2161044
B20: May | C20: =Yogesh!AC7+Ashraf!AC7+Rahul!AC7+Minesh!AC7 -> 18380018 | D20: =Yogesh!AD7+Ashraf!AD7+Rahul!AD7+Minesh!AD7 -> 10887971 | E20: 28895197 | F20: =D20-E20 -> -18007226 | G20: 7234307 | H20: =$H$13/12 -> 10120500 | I20: =H20-E20 -> -18774697 | J20: =(E20-H20)/E20 -> 0.64975148 | K20: =H20*4 -> 40482000 | L20: =(K20-C20)/K20 -> 0.5459706 | Q20: SPP | R20: =SUMIF(Yogesh!$J$9:$J$123,"SPP",Yogesh!$N$9:$N$124) -> 5411008 | S20: =SUMIF(Ashraf!$J$9:$J$125,"SPP",Ashraf!$N$9:$N$126) -> 8788209 | T20: =SUMIF(Rahul!$J$9:$J$123,"SPP",Rahul!$N$9:$N$124) -> 4159739 | U20: =SUMIF(Minesh!$J$9:$J$123,"SPP",Minesh!$N$9:$N$124) -> 6573780 | V20: =SUM(R20:U20) -> 24932736 | X20: SPP | Y20: =SUM(R20:X20) -> 49865472
B21: June | C21: =Yogesh!AC8+Ashraf!AC8+Rahul!AC8+Minesh!AC8 -> 7996136 | D21: =Yogesh!AD8+Ashraf!AD8+Rahul!AD8+Minesh!AD8 -> 12237563 | E21: 9159288 | F21: =D21-E21 -> 3078275 | G21: 12189407 | H21: =$H$13/12 -> 10120500 | I21: =H21-E21 -> 961212 | J21: =(E21-H21)/E21 -> -0.10494397 | K21: =H21*4 -> 40482000 | L21: =(K21-C21)/K21 -> 0.80247676 | Q21: Relocation | R21: =SUMIF(Yogesh!$J$10:$J$124,"Relocation",Yogesh!$N$10:$N$125) -> 3348000 | S21: =SUMIF(Ashraf!$J$10:$J$126,"Relocation",Ashraf!$N$10:$N$127) -> 2065000 | T21: =SUMIF(Rahul!$J$10:$J$124,"Relocation",Rahul!$N$10:$N$125) -> 355000 | U21: =SUMIF(Minesh!$J$10:$J$124,"Relocation",Minesh!$N$10:$N$125) -> 1460000 | V21: =SUM(R21:U21) -> 7228000 | X21: Relocation | Y21: =SUM(R21:X21) -> 14456000
B22: July | C22: =Yogesh!AC9+Ashraf!AC9+Rahul!AC9+Minesh!AC9 -> 9993977 | D22: =Yogesh!AD9+Ashraf!AD9+Rahul!AD9+Minesh!AD9 -> 8059011 | E22: 11691476 | F22: =D22-E22 -> -3632465 | G22: 9044062 | H22: =$H$13/12 -> 10120500 | I22: =H22-E22 -> -1570976 | J22: =(E22-H22)/E22 -> 0.13436935 | K22: =H22*4 -> 40482000 | L22: =(K22-C22)/K22 -> 0.75312541 | Q22: Software | R22: =SUMIF(Yogesh!$J$11:$J$125,"Software",Yogesh!$N$11:$N$126) -> 1378000 | S22: =SUMIF(Ashraf!$J$11:$J$127,"Software",Ashraf!$N$11:$N$128) -> 0 | T22: =SUMIF(Rahul!$J$11:$J$125,"Software",Rahul!$N$11:$N$126) -> 0 | U22: =SUMIF(Minesh!$J$11:$J$125,"Software",Minesh!$N$11:$N$126) -> 0 | V22: =SUM(R22:U22) -> 1378000 | X22: Software | Y22: =SUM(R22:X22) -> 2756000
B23: August | C23: =Yogesh!AC10+Ashraf!AC10+Rahul!AC10+Minesh!AC10 -> 13796991 | D23: =Yogesh!AD10+Ashraf!AD10+Rahul!AD10+Minesh!AD10 -> 8512281 | E23: 9427885 | F23: =D23-E23 -> -915604 | G23: 10386133 | H23: =$H$13/12 -> 10120500 | I23: =H23-E23 -> 692615 | J23: =(E23-H23)/E23 -> -0.073464515 | K23: =H23*4 -> 40482000 | L23: =(K23-C23)/K23 -> 0.65918208 | Q23: BD Charges | R23: =SUMIF(Yogesh!$J$12:$J$126,"BD Charges",Yogesh!$N$12:$N$127) -> 22500 | S23: =SUMIF(Ashraf!$J$12:$J$128,"BD Charges",Ashraf!$N$12:$N$129) -> 0 | T23: =SUMIF(Rahul!$J$12:$J$126,"BD Charges",Rahul!$N$12:$N$127) -> 80000 | U23: =SUMIF(Minesh!$J$12:$J$126,"BD Charges",Minesh!$N$12:$N$127) -> 106000 | V23: =SUM(R23:U23) -> 208500 | X23: BD Charges | Y23: =SUM(R23:X23) -> 417000
B24: September | C24: =Yogesh!AC11+Ashraf!AC11+Rahul!AC11+Minesh!AC11 -> 13836161 | D24: =Yogesh!AD11+Ashraf!AD11+Rahul!AD11+Minesh!AD11 -> 5645535 | E24: 9911793 | F24: =D24-E24 -> -4266258 | G24: 6448434 | H24: =$H$13/12 -> 10120500 | I24: =H24-E24 -> 208707 | J24: =(E24-H24)/E24 -> -0.021056432 | K24: =H24*4 -> 40482000 | L24: =(K24-C24)/K24 -> 0.65821449 | Q24: Retrofit kit | R24: =SUMIF(Yogesh!$J$13:$J$127,"Retrofit kit",Yogesh!$N$13:$N$128) -> 25643885 | S24: =SUMIF(Ashraf!$J$13:$J$129,"Retrofit kit",Ashraf!$N$13:$N$130) -> 0 | T24: =SUMIF(Rahul!$J$13:$J$127,"Retrofit kit",Rahul!$N$13:$N$128) -> 2638700 | U24: =SUMIF(Minesh!$J$13:$J$127,"Minesh",Rahul!$N$13:$N$128) -> 0 | V24: =SUM(R24:U24) -> 28282585 | X24: Retrofit kit | Y24: =SUM(R24:X24) -> 56565170
B25: October | C25: =Yogesh!AC12+Ashraf!AC12+Rahul!AC12+Minesh!AC12 -> 11308134 | D25: =Yogesh!AD12+Ashraf!AD12+Rahul!AD12+Minesh!AD12 -> 8712367 | E25: 8097887 | F25: =D25-E25 -> 614480 | G25: 6480022 | H25: =$H$13/12 -> 10120500 | I25: =H25-E25 -> 2022613 | J25: =(E25-H25)/E25 -> -0.24977046 | K25: =H25*4 -> 40482000 | L25: =(K25-C25)/K25 -> 0.72066266 | Q25: Upgrade kit | R25: =SUMIF(Yogesh!$J$14:$J$128,"Upgrade kit",Yogesh!$N$14:$N$129) -> 112959 | S25: =SUMIF(Ashraf!$J$14:$J$130,"Upgrade kit",Ashraf!$N$14:$N$131) -> 1499595 | T25: =SUMIF(Rahul!$J$14:$J$128,"Upgrade kit",Rahul!$N$14:$N$129) -> 0 | U25: =SUMIF(Minesh!$J$14:$J$128,"Upgrade kit",Minesh!$N$14:$N$129) -> 0 | V25: =SUM(R25:U25) -> 1612554 | X25: Upgrade kit | Y25: =SUM(R25:X25) -> 3225108
B26: November | C26: =Yogesh!AC13+Ashraf!AC13+Rahul!AC13+Minesh!AC13 -> 14607524 | D26: =Yogesh!AD13+Ashraf!AD13+Rahul!AD13+Minesh!AD13 -> 6184871 | E26: 5314010 | F26: =D26-E26 -> 870861 | G26: 4773358 | H26: =$H$13/12 -> 10120500 | I26: =H26-E26 -> 4806490 | J26: =(E26-H26)/E26 -> -0.90449397 | K26: =H26*4 -> 40482000 | L26: =(K26-C26)/K26 -> 0.63916002 | Q26: Training | R26: =SUMIF(Yogesh!$J$15:$J$129,"Training",Yogesh!$N$15:$N$130) -> 0 | S26: =SUMIF(Ashraf!$J$15:$J$131,"Training",Ashraf!$N$15:$N$132) -> 0 | T26: =SUMIF(Rahul!$J$15:$J$129,"Training",Rahul!$N$15:$N$130) -> 0 | U26: =SUMIF(Minesh!$J$15:$J$129,"Training",Minesh!$N$15:$N$130) -> 0 | V26: =SUM(R26:U26) -> 0 | X26: Training | Y26: =SUM(R26:X26) -> 0
B27: December | C27: =Yogesh!AC14+Ashraf!AC14+Rahul!AC14+Minesh!AC14 -> 8793736 | D27: =Yogesh!AD14+Ashraf!AD14+Rahul!AD14+Minesh!AD14 -> 5635763 | E27: 6354121 | F27: =D27-E27 -> -718358 | G27: 7368251 | H27: =$H$13/12 -> 10120500 | I27: =H27-E27 -> 3766379 | J27: =(E27-H27)/E27 -> -0.59274587 | K27: =H27*4 -> 40482000 | L27: =(K27-C27)/K27 -> 0.78277417 | Q27: Midlife Upgrade | R27: =SUMIF(Yogesh!$J$16:$J$130,"Midlife Upgrade",Yogesh!$N$16:$N$131) -> 0 | S27: =SUMIF(Ashraf!$J$16:$J$132,"Midlife Upgrade",Ashraf!$N$16:$N$133) -> 1846770 | T27: =SUMIF(Rahul!$J$16:$J$130,"Midlife Upgrade",Rahul!$N$16:$N$131) -> 15947586 | U27: =SUMIF(Minesh!$J$16:$J$130,"Midlife Upgrade",Minesh!$N$16:$N$131) -> 694970 | V27: =SUM(R27:U27) -> 18489326 | X27: Midlife Upgrade | Y27: =SUM(R27:X27) -> 36978652
B28: Total | C28: =SUM(C16:C27) -> 201107949 | D28: =SUM(D16:D27) -> 132310920 | E28: =SUM(E16:E27) -> 128881401 | F28: =SUM(F16:F27) -> 3429519 | H28: =SUM(H16:H27) -> 121446000 | I28: =SUM(I16:I27) -> -7435401 | K28: =SUM(K16:K27) -> 485784000 | L28: =(K28-C28)/K28 -> 0.58601364 | Q28: Total | R28: =SUM(R18:R27) -> 42515204 | S28: =SUM(S18:S27) -> 20257724 | T28: =SUM(T18:T27) -> 29846308 | U28: =SUM(U18:U27) -> 15171975 | V28: =SUM(R28:U28) -> 107791211 | X28: Total | Y28: =SUM(Y18:Y27) -> 215582422
H30: 107487000 | K30: HIT RATE | L30: =D45/C45 -> 0.5409598 | Q30: Product type | R30: Gajendra | S30: Pradeep | T30: Sasi | V30: South
B31: SOUTH | Q31: Contract | R31: =SUMIF(Gajendra!$J$7:$J$109,"Contract",Gajendra!$N$7:$N$110) -> 5393822.9 | S31: =SUMIF(Pradeep!$J$7:$J$121,"Contract",Pradeep!$N$7:$N$122) -> 5735921 | T31: =SUMIF(Sasi!$J$7:$J$125,"Contract",Sasi!$N$7:$N$126) -> 7382731 | V31: =SUM(R31:U31) -> 18512475
B32: Month | C32: Offers/Value | D32: Order Received | E32: *Order Booked | F32: Dev OR vs Booked | G32: *Orders In-Hand | H32: BU/Monthly | I32: Booked vs BU | J32: % Dev | K32: Offer BU Monthly | L32: % Dev | Q32: BD Spare | R32: =SUMIF(Gajendra!$J$8:$J$110,"BD Spare",Gajendra!$N$8:W34) -> 1640845.2 | S32: =SUMIF(Pradeep!$J$8:$J$122,"BD Spare",Pradeep!$N$8:X34) -> 0 | T32: =SUMIF(Sasi!$J$9:$J$126,"BD Spare",Sasi!$N$9:Y35) -> 1894886 | V32: =SUM(R32:U32) -> 3535731.2
B33: Januray | C33: =Gajendra!AD5+Pradeep!AD4+Sasi!AD4 -> 25413870 | D33: =Gajendra!AE5+Pradeep!AE4+Sasi!AE4 -> 15621491 | E33: 7293960 | F33: =D33-E33 -> 8327531.3 | H33: =$H$30/12 -> 8957250 | I33: =H33-E33 -> 1663290 | J33: =(E33-H33)/E33 -> -0.22803662 | K33: =H33*4 -> 35829000 | L33: =(K33-C33)/K33 -> 0.29068995 | Q33: SPP | R33: =SUMIF(Gajendra!$J$9:$J$111,"SPP",Gajendra!$N$9:$N$111) -> 13110148 | S33: =SUMIF(Pradeep!$J$9:$J$123,"SPP",Pradeep!$N$9:$N$124) -> 6566455 | T33: =SUMIF(Sasi!$J$10:$J$127,"SPP",Sasi!$N$10:$N$128) -> 13729354 | V33: =SUM(R33:U33) -> 33405957
B34: Febraury | C34: =Gajendra!AD6+Pradeep!AD5+Sasi!AD5 -> 11306008 | D34: =Gajendra!AE6+Pradeep!AE5+Sasi!AE5 -> 4063710.4 | E34: 6764704 | F34: =D34-E34 -> -2700993.6 | G34: 4655891 | H34: =$H$30/12 -> 8957250 | I34: =H34-E34 -> 2192546 | J34: =(E34-H34)/E34 -> -0.32411559 | K34: =H34*4 -> 35829000 | L34: =(K34-C34)/K34 -> 0.68444534 | Q34: Relocation | R34: =SUMIF(Gajendra!$J$10:$J$111,"Relocation",Gajendra!$N$10:$N$111) -> 1790070 | S34: =SUMIF(Pradeep!$J$10:$J$124,"Relocation",Pradeep!$N$10:$N$125) -> 260000 | T34: =SUMIF(Sasi!$J$11:$J$128,"Relocation",Sasi!$N$11:$N$129) -> 5287040 | V34: =SUM(R34:U34) -> 7337110
B35: March | C35: =Gajendra!AD7+Pradeep!AD6+Sasi!AD6 -> 14264905 | D35: =Gajendra!AE7+Pradeep!AE6+Sasi!AE6 -> 7013109.6 | E35: 9361455 | F35: =D35-E35 -> -2348345.4 | G35: 3686928 | H35: =$H$30/12 -> 8957250 | I35: =H35-E35 -> -404205 | J35: =(E35-H35)/E35 -> 0.043177583 | K35: =H35*4 -> 35829000 | L35: =(K35-C35)/K35 -> 0.60186148 | Q35: Software | R35: =SUMIF(Gajendra!$J$11:$J$111,"Software",Gajendra!$N$11:$N$111) -> 0 | S35: =SUMIF(Pradeep!$J$11:$J$125,"Software",Pradeep!$N$11:$N$126) -> 0 | T35: =SUMIF(Sasi!$J$12:$J$129,"Software",Sasi!$N$12:$N$130) -> 0 | V35: =SUM(R35:U35) -> 0
B36: April | C36: =Gajendra!AD8+Pradeep!AD7+Sasi!AD7 -> 24355664 | D36: =Gajendra!AE8+Pradeep!AE7+Sasi!AE7 -> 8793519.6 | E36: 8748821 | F36: =D36-E36 -> 44698.58 | G36: 1700874 | H36: =$H$30/12 -> 8957250 | I36: =H36-E36 -> 208429 | J36: =(E36-H36)/E36 -> -0.023823667 | K36: =H36*4 -> 35829000 | L36: =(K36-C36)/K36 -> 0.32022486 | Q36: BD Charges | R36: =SUMIF(Gajendra!$J$12:$J$111,"BD Charges",Gajendra!$N$12:$N$111) -> 33000 | S36: =SUMIF(Pradeep!$J$12:$J$126,"BD Charges",Pradeep!$N$12:$N$127) -> 38500 | T36: =SUMIF(Sasi!$J$13:$J$130,"BD Charges",Sasi!$N$13:$N$131) -> 0 | V36: =SUM(R36:U36) -> 71500
B37: May | C37: =Gajendra!AD9+Pradeep!AD8+Sasi!AD8 -> 7475519.3 | D37: =Gajendra!AE9+Pradeep!AE8+Sasi!AE8 -> 6251988 | E37: 1124932 | F37: =D37-E37 -> 5127056 | G37: 7883167 | H37: =$H$30/12 -> 8957250 | I37: =H37-E37 -> 7832318 | J37: =(E37-H37)/E37 -> -6.9624813 | K37: =H37*4 -> 35829000 | L37: =(K37-C37)/K37 -> 0.79135562 | Q37: Retrofit kit | R37: =SUMIF(Gajendra!$J$13:$J$111,"Gajendra",Rahul!$N$13:$N$128) -> 0 | S37: =SUMIF(Pradeep!$J$13:$J$127,"Pradeep",Rahul!$N$13:$N$128) -> 0 | T37: =SUMIF(Sasi!$J$14:$J$131,"Retrofit kit",Sasi!$N$14:$N$132) -> 3345258 | V37: =SUM(R37:U37) -> 3345258
B38: June | C38: =Gajendra!AD10+Pradeep!AD9+Sasi!AD9 -> 9956476 | D38: =Gajendra!AE10+Pradeep!AE9+Sasi!AE9 -> 6489478.2 | E38: 9214306 | F38: =D38-E38 -> -2724827.8 | G38: 4008704 | H38: =$H$30/12 -> 8957250 | I38: =H38-E38 -> -257056 | J38: =(E38-H38)/E38 -> 0.027897489 | K38: =H38*4 -> 35829000 | L38: =(K38-C38)/K38 -> 0.72211125 | Q38: Upgrade kit | R38: =SUMIF(Gajendra!$J$14:$J$112,"Upgrade kit",Gajendra!$N$14:$N$113) -> 1954675 | S38: =SUMIF(Pradeep!$J$14:$J$128,"Upgrade kit",Pradeep!$N$14:$N$129) -> 2693572 | T38: =SUMIF(Sasi!$J$15:$J$132,"Upgrade kit",Sasi!$N$15:$N$133) -> 1017585 | V38: =SUM(R38:U38) -> 5665832
B39: July | C39: =Gajendra!AD11+Pradeep!AD10+Sasi!AD10 -> 19793873 | D39: =Gajendra!AE11+Pradeep!AE10+Sasi!AE10 -> 6787163.4 | E39: 9229190 | F39: =D39-E39 -> -2442026.6 | G39: 3704956 | H39: =$H$30/12 -> 8957250 | I39: =H39-E39 -> -271940 | J39: =(E39-H39)/E39 -> 0.029465208 | K39: =H39*4 -> 35829000 | L39: =(K39-C39)/K39 -> 0.44754604 | Q39: Training | R39: =SUMIF(Gajendra!$J$15:$J$113,"Training",Gajendra!$N$15:$N$114) -> 0 | S39: =SUMIF(Pradeep!$J$15:$J$129,"Training",Pradeep!$N$15:$N$130) -> 0 | T39: =SUMIF(Sasi!$J$16:$J$133,"Training",Sasi!$N$16:$N$134) -> 0 | V39: =SUM(R39:U39) -> 0
B40: August | C40: =Gajendra!AD12+Pradeep!AD11+Sasi!AD11 -> 16128864 | D40: =Gajendra!AE12+Pradeep!AE11+Sasi!AE11 -> 9060325.6 | E40: 8493405 | F40: =D40-E40 -> 566920.59 | G40: 6470925 | H40: =$H$30/12 -> 8957250 | I40: =H40-E40 -> 463845 | J40: =(E40-H40)/E40 -> -0.054612373 | K40: =H40*4 -> 35829000 | L40: =(K40-C40)/K40 -> 0.54983772 | Q40: Midlife Upgrade | R40: =SUMIF(Gajendra!$J$16:$J$114,"Midlife Upgrade",Gajendra!$N$16:$N$115) -> 6822682.2 | S40: =SUMIF(Pradeep!$J$16:$J$130,"Midlife Upgrade",Pradeep!$N$16:$N$131) -> 2089731 | T40: =SUMIF(Sasi!$J$17:$J$134,"Midlife Upgrade",Sasi!$N$17:$N$135) -> 3705155.7 | V40: =SUM(R40:U40) -> 12617569
B41: September | C41: =Gajendra!AD13+Pradeep!AD12+Sasi!AD12 -> 9615526 | D41: =Gajendra!AE13+Pradeep!AE12+Sasi!AE12 -> 4656791.8 | E41: 8975078 | F41: =D41-E41 -> -4318286.2 | G41: 2238093 | H41: =$H$30/12 -> 8957250 | I41: =H41-E41 -> -17828 | J41: =(E41-H41)/E41 -> 0.0019863894 | K41: =H41*4 -> 35829000 | L41: =(K41-C41)/K41 -> 0.73162729 | Q41: Total | R41: =SUM(R31:R40) -> 30745243 | S41: =SUM(S31:S40) -> 17384179 | T41: =SUM(T31:T40) -> 36362010 | V41: =SUM(V31:V40) -> 84491432
B42: October | C42: =Gajendra!AD14+Pradeep!AD13+Sasi!AD13 -> 22510217 | D42: =Gajendra!AE14+Pradeep!AE13+Sasi!AE13 -> 8516306.7 | E42: 8399872 | F42: =D42-E42 -> 116434.72 | G42: 7691541 | H42: =$H$30/12 -> 8957250 | I42: =H42-E42 -> 557378 | J42: =(E42-H42)/E42 -> -0.066355535 | K42: =H42*4 -> 35829000 | L42: =(K42-C42)/K42 -> 0.37173192
...

Sheet Yogesh
AB1: Month wise data
A2: KARDEX INDIA - LIVE OFFER FUNEL - YOGESH - WEST | AB2: Month | AC2: Offers Total | AD2: Order received | AE2: Forecast | AF2: Forecast- Po Received
U3: Total Offered Value | V3: =SUM(N7:N408) -> 63775451 | AB3: January | AC3: =SUMIF($O$7:$O$408,"January",$N$7:$N$408) -> 7550534 | AD3: =SUMIF($U$7:$U$408,"January",$T$7:$T$408) -> 408580 | AE3: =SUMIF($P$7:$P$427,"January",$N$7:$N$427) -> 1503580 | AF3: =AE3-AD3 -> 1095000
A4: Total Offers | B4: =COUNTA(B7:B1429) -> 96 | R4: =SUMIFS(N13:N24,P13:P24,"April",J13:J24,"Contract") -> 0 | U4: Order Received | V4: =SUM(T7:T408) -> 45660707 | AB4: February | AC4: =SUMIF($O$7:$O$408,"February",$N$7:$N$408) -> 2845724 | AD4: =SUMIF($U$7:$U$408,"February",$T$7:$T$408) -> 1833000 | AE4: =SUMIF($P$7:$P$427,"February",$N$7:$N$427) -> 738000 | AF4: =AE4-AD4 -> -1095000
U5: Open Funnel | V5: =SUM(V7:V408) -> 13599894 | Y5: * Updated by Girija | AB5: March | AC5: =SUMIF($O$7:$O$408,"March",$N$7:$N$408) -> 27185038 | AD5: =SUMIF($U$7:$U$408,"March",$T$7:$T$408) -> 799106 | AE5: =SUMIF($P$7:$P$427,"March",$N$7:$N$427) -> 799106 | AF5: =AE5-AD5 -> 0
A6: SL | B6: Reg Date | C6: Company | D6: Location | E6: Department | F6: Contact Person Name | G6: Contact Number | H6: E-Mail ID | I6: Machine Serial Number | J6: Product Type | K6: Lead | L6: Offer Reference Number | M6: Offer Reference Date | N6: Offer Value | O6: Offer Month | P6: PO Expected Month | Q6: Probabality in Percentage | R6: PO Number | S6: PO Date | T6: PO Value | U6: PO Received Month | V6: Open Funnel | W6: Remarks | X6: Status | Y6: Booking Date in SAP B1 | Z6: Offer Entered in CRM | AA6: Offer Closed in CRM | AB6: April | AC6: =SUMIF($O$7:$O$408,"April",$N$7:$N$408) -> 380716 | AD6: =SUMIF($U$7:$U$408,"April",$T$7:$T$408) -> 29031268 | AE6: =SUMIF($P$7:$P$427,"April",$N$7:$N$427) -> 29793925 | AF6: =AE6-AD6 -> 762657
A7: 1 | B7: 45667 | C7: Tata Motors LTD | D7: Pune | E7: D blockstore | F7: pankaj Badhe | G7: 8237003520 | H7: badhe.pankaj@tatamotors.com | I7: 16002093/001 | J7: Relocation | K7: No | L7: KXIND/W/SPP/YD24-01 | M7: 45394 | N7: 0 | O7: January | P7: March | Q7: 0.5 | T7: 0 | V7: =Table62689345[[#This Row],[Offer Value]]-Table62689345[[#This Row],[PO Value]] -> 0 | W7: Project Postpone with no confirm date. | AB7: May | AC7: =SUMIF($O$7:$O$408,"May",$N$7:$N$408) -> 1732000 | AD7: =SUMIF($U$7:$U$408,"May",$T$7:$T$408) -> 1855692 | AE7: =SUMIF($P$7:$P$427,"May",$N$7:$N$427) -> 2155128 | AF7: =AE7-AD7 -> 299436
A8: 2 | C8: Tata Motors LTD | D8: Pune | E8: D blockstore | F8: pankaj Badhe | G8: 8237003521 | H8: badhe.pankaj@tatamotors.com | I8: 16002093/002 | J8: Relocation | K8: No | L8: KXIND/W/SPP/YD24-01 | M8: 45394 | N8: 0 | O8: January | P8: March | Q8: 0.5 | T8: 0 | V8: =Table62689345[[#This Row],[Offer Value]]-Table62689345[[#This Row],[PO Value]] -> 0 | W8: Project Postpone with no confirm date. | AB8: June | AC8: =SUMIF($O$7:$O$408,"June",$N$7:$N$408) -> 824959 | AD8: =SUMIF($U$7:$U$408,"June",$T$7:$T$408) -> 2134682 | AE8: =SUMIF($P$7:$P$427,"June",$N$7:$N$427) -> 2185972 | AF8: =AE8-AD8 -> 51290
A9: 3 | B9: 45667 | C9: Tetra Pak India Pvt Ltd | D9: Pune | E9: renovation store | F9: Vikas Patil | G9: 88888 78141 | H9: vikas.patil@tetrapak.com | I9: 20004190/001 | J9: Relocation | K9: No | L9: KXIND/W/SPP/YD24-02 | M9: 45394 | N9: 0 | O9: January | P9: March | Q9: 0.5 | T9: 0 | V9: =Table62689345[[#This Row],[Offer Value]]-Table62689345[[#This Row],[PO Value]] -> 0 | W9: Project Postpone with no confirm date. | AB9: July | AC9: =SUMIF($O$7:$O$408,"July",$N$7:$N$408) -> 2136554 | AD9: =SUMIF($U$7:$U$408,"July",$T$7:$T$408) -> 1689392 | AE9: =SUMIF($P$7:$P$427,"July",$N$7:$N$427) -> 1752032 | AF9: =AE9-AD9 -> 62640
A10: 4 | C10: Tetra Pak India Pvt Ltd | D10: Pune | E10: renovation store | F10: Vikas Patil | G10: 88888 78141 | H10: vikas.patil@tetrapak.com | I10: 20004190/002 | J10: Relocation | K10: No | L10: KXIND/W/SPP/YD24-02 | M10: 45394 | N10: 0 | O10: January | P10: March | Q10: 0.5 | T10: 0 | V10: =Table62689345[[#This Row],[Offer Value]]-Table62689345[[#This Row],[PO Value]] -> 0 | W10: Project Postpone with no confirm date. | AB10: August | AC10: =SUMIF($O$7:$O$408,"August",$N$7:$N$408) -> 3732804 | AD10: =SUMIF($U$7:$U$408,"August",$T$7:$T$408) -> 1688932 | AE10: =SUMIF($P$7:$P$427,"August",$N$7:$N$427) -> 2652512 | AF10: =AE10-AD10 -> 963580
A11: 5 | C11: Tetra Pak India Pvt Ltd | D11: Pune | E11: renovation store | F11: Vikas Patil | G11: 88888 78142 | H11: vikas.patil@tetrapak.com | I11: 20004190/003 | J11: Relocation | K11: No | L11: KXIND/W/SPP/YD24-02 | M11: 45394 | N11: 0 | O11: January | P11: March | Q11: 0.5 | T11: 0 | V11: =Table62689345[[#This Row],[Offer Value]]-Table62689345[[#This Row],[PO Value]] -> 0 | W11: Project Postpone with no confirm date. | AB11: September | AC11: =SUMIF($O$7:$O$408,"September",$N$7:$N$408) -> 7153666 | AD11: =SUMIF($U$7:$U$408,"September",$T$7:$T$408) -> 1746740 | AE11: =SUMIF($P$7:$P$427,"September",$N$7:$N$427) -> 4109040 | AF11: =AE11-AD11 -> 2362300
A12: 6 | B12: 45667 | C12: Schaeffler India Limited | D12: Pune | E12: Tool Room | F12: Sandip Gaikwad | G12: 7507568788 | H12: gaikwsnd@schaeffler.com; | I12: 17003031/001 | J12: Retrofit kit | K12: Yes | L12: KXIND/W/YD/SPP/25069R | M12: 45897 | N12: 2031058 | O12: August | P12: September | Q12: 0.5 | R12: 7001063894 | S12: 45922 | T12: 836318 | U12: September | V12: =Table62689345[[#This Row],[Offer Value]]-Table62689345[[#This Row],[PO Value]] -> 1194740 | Z12: Yes | AB12: October | AC12: =SUMIF($O$7:$O$408,"October",$N$7:$N$408) -> 443773 | AD12: =SUMIF($U$7:$U$408,"October",$T$7:$T$408) -> 2094893 | AE12: =SUMIF($P$7:$P$427,"October",$N$7:$N$427) -> 1603555 | AF12: =AE12-AD12 -> -491338
A13: 7 | B13: 45667 | C13: Mahindra Vehicals Mf LTD | D13: Pune | E13: P Blk Store | F13: Anant Jadhav | G13: 9503006627 | H13: anant.jadhav@mahindra.com | I13: 13000097/001 | J13: Contract | K13: No | L13: KXIND/W/YD/MC/24032 | M13: 45419 | N13: 56000 | O13: January | P13: June | Q13: 0.7 | R13: 6500007595 | S13: 45820 | T13: 56000 | U13: June | V13: =Table62689345[[#This Row],[PO Value]]-Table62689345[[#This Row],[Offer Value]] -> 0 | W13: PO received with software contract | AB13: November | AC13: =SUMIF($O$7:$O$408,"November",$N$7:$N$408) -> 7556364 | AD13: =SUMIF($U$7:$U$408,"November",$T$7:$T$408) -> 1087080 | AE13: =SUMIF($P$7:$P$427,"November",$N$7:$N$427) -> 1673209 | AF13: =AE13-AD13 -> 586129
A14: 8 | C14: Mahindra Vehicals Mf LTD | D14: Pune | E14: P Blk Store | F14: Anant Jadhav | G14: 9503006627 | H14: anant.jadhav@mahindra.com | I14: 17001697/001 | J14: Contract | K14: No | L14: KXIND/W/YD/MC/24032 | M14: 45419 | N14: 56000 | O14: January | P14: June | Q14: 0.7 | R14: 6500007595 | S14: 45820 | T14: 56000 | U14: June | V14: =Table62689345[[#This Row],[PO Value]]-Table62689345[[#This Row],[Offer Value]] -> 0 | W14: PO received with software contract | AB14: December | AC14: =SUMIF($O$7:$O$408,"December",$N$7:$N$408) -> 2233319 | AD14: =SUMIF($U$7:$U$408,"December",$T$7:$T$408) -> 1291342 | AE14: =SUMIF($P$7:$P$427,"December",$N$7:$N$427) -> 14809392 | AF14: =AE14-AD14 -> 13518050
A15: 9 | C15: Mahindra Vehicals Mf LTD | D15: Pune | E15: P Blk Store | F15: Anant Jadhav | G15: 9503006627 | H15: anant.jadhav@mahindra.com | I15: 17001697/002 | J15: Contract | K15: No | L15: KXIND/W/YD/MC/24032 | M15: 45419 | N15: 56000 | O15: January | P15: June | Q15: 0.7 | R15: 6500007595 | S15: 45820 | T15: 56000 | U15: June | V15: =Table62689345[[#This Row],[PO Value]]-Table62689345[[#This Row],[Offer Value]] -> 0 | W15: PO received with software contract
A16: 10 | C16: Mahindra Vehicals Mf LTD | D16: Pune | E16: P Blk Store | F16: Anant Jadhav | G16: 9503006627 | H16: anant.jadhav@mahindra.com | I16: 17001697/003 | J16: Contract | K16: No | L16: KXIND/W/YD/MC/24032 | M16: 45419 | N16: 56000 | O16: January | P16: June | Q16: 0.7 | R16: 6500007595 | S16: 45820 | T16: 56000 | U16: June | V16: =Table62689345[[#This Row],[PO Value]]-Table62689345[[#This Row],[Offer Value]] -> 0 | W16: PO received with software contract
A17: 11 | C17: Mahindra Vehicals Mf LTD | D17: Pune | E17: P Blk Store | F17: Anant Jadhav | G17: 9503006627 | H17: anant.jadhav@mahindra.com | I17: 17001697/004 | J17: Contract | K17: No | L17: KXIND/W/YD/MC/24032 | M17: 45419 | N17: 56000 | O17: January | P17: June | Q17: 0.7 | R17: 6500007595 | S17: 45820 | T17: 56000 | U17: June | V17: =Table62689345[[#This Row],[PO Value]]-Table62689345[[#This Row],[Offer Value]] -> 0 | W17: PO received with software contract
A18: 12 | C18: Mahindra Vehicals Mf LTD | D18: Pune | E18: P Blk Store | F18: Anant Jadhav | G18: 9503006627 | H18: anant.jadhav@mahindra.com | I18: 17004630/001 | J18: Contract | K18: No | L18: KXIND/W/YD/MC/24032 | M18: 45419 | N18: 56000 | O18: January | P18: June | Q18: 0.7 | R18: 6500007595 | S18: 45820 | T18: 56000 | U18: June | V18: =Table62689345[[#This Row],[PO Value]]-Table62689345[[#This Row],[Offer Value]] -> 0 | W18: PO received with software contract
A19: 13 | C19: Mahindra Vehicals Mf LTD | D19: Pune | E19: P Blk Store | F19: Anant Jadhav | G19: 9503006627 | H19: anant.jadhav@mahindra.com | I19: 17004630/003 | J19: Contract | K19: No | L19: KXIND/W/YD/MC/24032 | M19: 45419 | N19: 56000 | O19: January | P19: June | Q19: 0.7 | R19: 6500007595 | S19: 45820 | T19: 56000 | U19: June | V19: =Table62689345[[#This Row],[PO Value]]-Table62689345[[#This Row],[Offer Value]] -> 0 | W19: PO received with software contract
A20: 14 | C20: Mahindra Vehicals Mf LTD | D20: Pune | E20: P Blk Store | F20: Anant Jadhav | G20: 9503006627 | H20: anant.jadhav@mahindra.com | I20: 17004630/002 | J20: Contract | K20: No | L20: KXIND/W/YD/MC/24032 | M20: 45419 | N20: 56000 | O20: January | P20: June | Q20: 0.7 | R20: 6500007595 | S20: 45820 | T20: 56000 | U20: June | V20: =Table62689345[[#This Row],[PO Value]]-Table62689345[[#This Row],[Offer Value]] -> 0 | W20: PO received with software contract
A21: 15 | B21: 45667 | C21: Bajaj Auto Ltd | D21: Pune | E21: Engine Assembly | F21: Rajkumar Ajabe | G21: 9613370060 | H21: rrajabe@bajajauto.co.in | I21: 17004630/003 | J21: SPP | K21: Yes | L21: KXIND/W/YD/SPP/25018 | M21: 45701 | N21: 141032 | O21: February | P21: June | Q21: 0.5 | R21: 5210059205 | S21: 45793 | T21: 95742 | U21: June | V21: =Table62689345[[#This Row],[PO Value]]-Table62689345[[#This Row],[Offer Value]] -> -45290
A22: 16 | B22: 45667 | C22: ITC Ltd | D22: Pune | E22: Engineering stores | F22: Navanath Ekatpure | G22: 9730478741 | H22: navanath.ekatpure@itc.in | I22: 09006715/001 | J22: SPP | K22: Yes | L22: KXIND/W/YD/SPP/24052 | M22: 45607 | N22: 739430 | O22: January | P22: May | Q22: 0.5 | R22: 4700392647 | S22: 25.04.2025 | T22: 709852 | U22: May | V22: =Table62689345[[#This Row],[PO Value]]-Table62689345[[#This Row],[Offer Value]] -> -29578 | Z22: Yes
A23: 138 | B23: 45922 | C23: Tata Motors LTD | D23: Pune | E23: Cblk Maint | F23: Amit sharma | G23: 9011018387 | H23: s.amit1@tatamotors.com | I23: 06008006/001 | J23: Software | K23: Yes | L23: KRIND/SA/OTH/520025 | M23: 45916 | N23: 1378000 | O23: September | P23: December | Q23: 0.3 | V23: =Table62689345[[#This Row],[Offer Value]]-Table62689345[[#This Row],[PO Value]] -> 1378000
A24: 18 | B24: 45667 | C24: TOP Hydrofit PVT LTD | D24: Pune | E24: stores | F24: Hemant tarate | G24: 9881134849 | H24: info@tophydrofit.com | I24: 11001071/001 | J24: SPP | K24: Yes | L24: KXIND/W/YD/SPP/24055 | M24: 45334 | N24: 0 | O24: January | P24: July | Q24: 0.3 | T24: 0 | V24: =Table62689345[[#This Row],[PO Value]]-Table62689345[[#This Row],[Offer Value]] -> 0
A25: 19 | B25: 45667 | C25: GIC Instruments Pvt Ltd | D25: Pune | E25: stores | F25: Ajinkya Desale | G25: 9403849891 | H25: ajinkya.dhekale@gicindia.com | I25: 08010151/001 | J25: SPP | K25: Yes | L25: KXIND/W/YD/SPP/24063 | M25: 12/12/204 | N25: 35000 | O25: January | P25: January | Q25: 0.7 | R25: 7356 | S25: 45667 | T25: 35000 | U25: January | V25: =Table62689345[[#This Row],[PO Value]]-Table62689345[[#This Row],[Offer Value]] -> 0 | Y25: 17/1/2025
A26: 20 | B26: 45667 | C26: Mahindra Vehicals Mf LTD | D26: Pune | E26: Pblock Logistics | F26: Rahul Adhav | G26: 8983467616 | H26: ADHAV.RAHUL@mahindra.com | I26: 17001697/004 | J26: SPP | K26: Yes | L26: KXIND/W/YD/SPP/24062 | M26: 45638 | N26: 647302 | O26: January | P26: September | Q26: 0.7 | R26: 66020580 | S26: 45957 | T26: 649648 | U26: October | V26: =Table62689345[[#This Row],[PO Value]]-Table62689345[[#This Row],[Offer Value]] -> 2346 | W26: Customer Budget Peocess unlock on 18th.April so request for Pricing on ARIBA will be received 2nd.Week of May | Z26: yes
A27: 21 | B27: 45668 | C27: Bosch Chassis Systems India Ltd | D27: Pune | E27: maintenance store | F27: Pratap Jagdale | G27: 9970010738 | H27: Pratap.Jagadale@in.bosch.com | I27: 19004857/001 | J27: Contract | K27: No | L27: KXIND/W/YD/MC/24066 | M27: 45644 | N27: 73500 | O27: January | P27: January | Q27: 1 | R27: 85375744 | S27: 45658 | T27: 73500 | U27: January | V27: =Table62689345[[#This Row],[PO Value]]-Table62689345[[#This Row],[Offer Value]] -> 0
A28: 22 | B28: 45668 | C28: Coesia India Pvt.Ltd. | D28: Pune | E28: stores | F28: D.Kadam | G28: 9552599231 | H28: dnyaneshwar.kadam@coesia.com | I28: 16000669/001 | J28: Contract | K28: No | L28: KXIND/W/YD/MC/24069 | M28: 45644 | N28: 83040 | O28: January | P28: January | Q28: 0.8 | R28: CGT250008 | S28: 45677 | T28: 83040 | U28: January | V28: =Table62689345[[#This Row],[PO Value]]-Table62689345[[#This Row],[Offer Value]] -> 0 | W28: PO with software contract S/C value 25043
A29: 23 | C29: Coesia India Pvt.Ltd. | D29: Pune | E29: stores | F29: D.Kadam | G29: 9552599231 | H29: dnyaneshwar.kadam@coesia.com | I29: 16000668/001 | J29: Contract | K29: No | L29: KXIND/W/YD/MC/24069 | M29: 45644 | N29: 83040 | O29: January | P29: January | Q29: 0.8 | R29: CGT250008 | S29: 45677 | T29: 83040 | U29: January | V29: =Table62689345[[#This Row],[PO Value]]-Table62689345[[#This Row],[Offer Value]] -> 0 | W29: PO with software contract S/C value 25043
A30: 24 | B30: 45668 | C30: Eagle Burgmann India Pvt Ltd | D30: Pune | E30: stores | F30: Mahesh Hole | G30: 9373850080 | H30: Mahesh.Hole@in.eagleburgmann.com | I30: 08004851/001 | J30: Contract | K30: No | L30: KXIND/W/YD/MC/24071 | M30: 45644 | N30: 160000 | O30: January | P30: February | Q30: 0.8 | R30: 2481406 | S30: 45673 | T30: 160000 | U30: February | V30: =Table62689345[[#This Row],[PO Value]]-Table62689345[[#This Row],[Offer Value]] -> 0
A31: 25 | B31: 45668 | C31: Harman International (I) Pvt Ltd | D31: Pune | E31: stores | F31: Santosh Deshmukh | G31: 9552599231 | H31: santosh.deshmukh@harman.com | I31: 19005224/001 | J31: Contract | K31: No | L31: KXIND/W/YD/MC/24067 | M31: 45644 | N31: 93000 | O31: January | P31: February | Q31: 0.8 | R31: 7700326717 | S31: 45779 | T31: 93000 | U31: February | V31: =Table62689345[[#This Row],[PO Value]]-Table62689345[[#This Row],[Offer Value]] -> 0
A32: 26 | C32: Harman International (I) Pvt Ltd | D32: Pune | E32: stores | F32: Santosh Deshmukh | G32: 9552599231 | H32: santosh.deshmukh@harman.com | I32: 19005224/002 | J32: Contract | K32: No | L32: KXIND/W/YD/MC/24067 | M32: 45644 | N32: 93000 | O32: January | P32: February | Q32: 0.8 | R32: 7700326717 | S32: 45779 | T32: 93000 | U32: February | V32: =Table62689345[[#This Row],[PO Value]]-Table62689345[[#This Row],[Offer Value]] -> 0
A33: 27 | C33: Harman International (I) Pvt Ltd | D33: Pune | E33: stores | F33: Santosh Deshmukh | G33: 9552599231 | H33: santosh.deshmukh@harman.com | I33: 19005224/003 | J33: Contract | K33: No | L33: KXIND/W/YD/MC/24067 | M33: 45644 | N33: 93000 | O33: January | P33: February | Q33: 0.8 | R33: 7700326717 | S33: 45779 | T33: 93000 | U33: February | V33: =Table62689345[[#This Row],[PO Value]]-Table62689345[[#This Row],[Offer Value]] -> 0
A34: 28 | C34: Harman International (I) Pvt Ltd | D34: Pune | E34: stores | F34: Santosh Deshmukh | G34: 9552599231 | H34: santosh.deshmukh@harman.com | I34: 23002397/001 | J34: Contract | K34: No | L34: KXIND/W/YD/MC/24067 | M34: 45644 | N34: 93000 | O34: January | P34: February | Q34: 0.8 | R34: 7700326717 | S34: 45779 | T34: 93000 | U34: February | V34: =Table62689345[[#This Row],[PO Value]]-Table62689345[[#This Row],[Offer Value]] -> 0
A35: 29 | B35: 45668 | C35: Klug avalon mechatronics | D35: Pune | E35: stores | F35: N.Patil | G35: 9271117805 | H35: rms@klugavalon.com | I35: 16007512/001 | J35: Contract | K35: No | L35: KXIND/W/YD/MC/24072 | M35: 45644 | N35: 60000 | O35: January | P35: February | Q35: 0.8 | R35: 7388 | S35: 45667 | T35: 60000 | U35: February | V35: =Table62689345[[#This Row],[PO Value]]-Table62689345[[#This Row],[Offer Value]] -> 0
A36: 30 | B36: 45668 | C36: Schaeffler India Limited | D36: Pune | E36: Tool Room | F36: Ananda. A | G36: 9923177609 | H36: asoduaan@schaeffler.com | I36: 19004014/001 | J36: Contract | K36: No | L36: KXIND/W/YD/MC/24076 | M36: 45653 | N36: 67000 | O36: January | P36: January | Q36: 0.8 | R36: 0042 / Y20 / 38369028 | S36: 45671 | T36: 67000 | U36: January | V36: =Table62689345[[#This Row],[PO Value]]-Table62689345[[#This Row],[Offer Value]] -> 0
A37: 31 | C37: Schaeffler India Limited | D37: Pune | E37: Tool Room | F37: Ananda. A | G37: 9923177609 | H37: asoduaan@schaeffler.com | I37: 102006187 | J37: Contract | K37: No | L37: KXIND/W/YD/MC/24076 | M37: 45653 | N37: 67000 | O37: January | P37: January | Q37: 0.8 | R37: 0042 / Y20 / 38414491 | S37: 45664 | T37: 67000 | U37: January | V37: =Table62689345[[#This Row],[PO Value]]-Table62689345[[#This Row],[Offer Value]] -> 0
A38: 32 | B38: 45668 | C38: Tetra Pak India Pvt Ltd | D38: Pune | E38: Spare stores | F38: Vivek Kamya | G38: +91 9850 8069 74 | H38: Vivek.Kyama@tetrapak.com | I38: 07009761/001 | J38: Contract | K38: No | L38: KXIND/W/YD/MC/24070 | M38: 45644 | N38: 96000 | O38: January | P38: February | Q38: 0.8 | R38: 927358056 | S38: 45672 | T38: 96000 | U38: February | V38: =Table62689345[[#This Row],[PO Value]]-Table62689345[[#This Row],[Offer Value]] -> 0
A39: 33 | B39: 45668 | C39: Tata motors passenger vehicles Limted (Tata Motors Ltd) | D39: Pune | E39: Logistics | F39: Ravindra wani | G39: 7276004059 | H39: ravindra.wani@tatamotors.com | I39: 08000931/001 | J39: Contract | K39: No | L39: KXIND/W/YD/MC/24057 | M39: 45424 | N39: 82080 | O39: January | P39: April | Q39: 0.7 | R39: 2265005504 | S39: 45754 | T39: 82080 | U39: April | V39: =Table62689345[[#This Row],[PO Value]]-Table62689345[[#This Row],[Offer Value]] -> 0
A40: 34 | C40: Tata motors passenger vehicles Limted (Tata Motors Ltd) | D40: Pune | E40: Logistics | F40: Ravindra wani | G40: 7276004060 | H40: ravindra.wani@tatamotors.com | I40: 08000931/002 | J40: Contract | K40: No | L40: KXIND/W/YD/MC/24057 | M40: 45424 | N40: 82080 | O40: January | P40: April | Q40: 0.7 | R40: 2265005504 | S40: 45754 | T40: 82080 | U40: April | V40: =Table62689345[[#This Row],[PO Value]]-Table62689345[[#This Row],[Offer Value]] -> 0
...

Sheet Ashraf
AB2: Month | AC2: Offers Total | AD2: Order received | AE2: Forecast | AF2: Forecast- Po Received
A3: KARDEX INDIA - LIVE OFFER FUNEL - ASHRAF - WEST | AB3: January | AC3: =SUMIF($O$8:$O$426,"January",$N$8:$N$426) -> 9757532 | AD3: =SUMIF($U$8:$U$426,"January",$T$8:$T$426) -> 2531948 | AE3: =SUMIF($P$8:$P$431,"January",$N$8:$N$431) -> 2967340 | AF3: =AE3-AD3 -> 435392
Q4: 0.01 | U4: Total Offered Value | V4: =SUM(N8:N426) -> 50584483 | AB4: February | AC4: =SUMIF($O$8:$O$426,"February",$N$8:$N$426) -> 4840185 | AD4: =SUMIF($U$8:$U$426,"February",$T$8:$T$426) -> 1652533 | AE4: =SUMIF($P$8:$P$431,"February",$N$8:$N$431) -> 1129500 | AF4: =AE4-AD4 -> -523033
A5: Total Offers | B5: =COUNTA(B8:B1466) -> 112 | U5: Order Received | V5: =SUM(T8:T426) -> 35560386 | AB5: March | AC5: =SUMIF($O$8:$O$426,"March",$N$8:$N$426) -> 2602772 | AD5: =SUMIF($U$8:$U$426,"March",$T$8:$T$426) -> 3651314 | AE5: =SUMIF($P$8:$P$431,"March",$N$8:$N$431) -> 4226358 | AF5: =AE5-AD5 -> 575044
U6: Open Funnel | V6: =SUM(V8:V426) -> 13539398 | Y6: * Updated by Girija | AB6: April | AC6: =SUMIF($O$8:$O$426,"April",$N$8:$N$426) -> 3583731 | AD6: =SUMIF($U$8:$U$426,"April",$T$8:$T$426) -> 1776550 | AE6: =SUMIF($P$8:$P$431,"April",$N$8:$N$431) -> 1926050 | AF6: =AE6-AD6 -> 149500
A7: SL | B7: Reg Date | C7: Company | D7: Location | E7: Department | F7: Contact Person Name | G7: Contact Number | H7: E-Mail ID | I7: Machine Serial Number | J7: Product Type | K7: Lead | L7: Offer Reference Number | M7: Offer Reference Date | N7: Offer Value | O7: Offer Month | P7: PO Expected Month | Q7: Probabality in Percentage | R7: PO Number | S7: PO Date | T7: PO Value | U7: PO Received Month | V7: Open Funnel | W7: Remarks | X7: Status | Y7: Booking Date in SAP B1 | Z7: Offer Entered in CRM | AA7: Offer Closed in CRM | AB7: May | AC7: =SUMIF($O$8:$O$426,"May",$N$8:$N$426) -> 5141304 | AD7: =SUMIF($U$8:$U$426,"May",$T$8:$T$426) -> 4694500 | AE7: =SUMIF($P$8:$P$431,"May",$N$8:$N$431) -> 5133652 | AF7: =AE7-AD7 -> 439152
A8: 1 | B8: 45666 | C8: Cummins Technologis India Pvt Ltd | D8: phaltan | E8: PCP1 | F8: Sagar Jagatap | G8: 9373155620 | H8: sagar.jagatap@cummins.com | I8: 18007324/001 | J8: Upgrade kit | K8: Yes | L8: KRIND/W/SPP/AB/24005 | M8: 45341 | N8: 1246800 | O8: January | P8: August | Q8: 1 | R8: IND8202828 | S8: 45751 | T8: 1029360 | U8: August | V8: 0 | Z8: Yes | AB8: June | AC8: =SUMIF($O$8:$O$426,"June",$N$8:$N$426) -> 5050287 | AD8: =SUMIF($U$8:$U$426,"June",$T$8:$T$426) -> 6037535 | AE8: =SUMIF($P$8:$P$431,"June",$N$8:$N$431) -> 6433266 | AF8: =AE8-AD8 -> 395731
A9: 2 | B9: 45666 | C9: Hiteco TMS India Pvt Ltd | D9: Pune | E9: Stores tool | F9: Wasim Sheikh | G9: 9881275059 | H9: XPNCN24@hmil.net | I9: 09008827/001 | J9: SPP | K9: Yes | L9: KRIND/W/SPP/AB24018 | M9: 45412 | N9: 604356 | O9: January | P9: August | Q9: 1 | V9: 0 | Z9: Yes | AB9: July | AC9: =SUMIF($O$8:$O$426,"July",$N$8:$N$426) -> 3175477 | AD9: =SUMIF($U$8:$U$426,"July",$T$8:$T$426) -> 3214688 | AE9: =SUMIF($P$8:$P$431,"July",$N$8:$N$431) -> 2640380 | AF9: =AE9-AD9 -> -574308
A10: 3 | B10: 45666 | C10: Bharat Electronics Ltd | D10: Pune | E10: Stores | F10: Vilas Khade | G10: 2022903115 | H10: vilaskhade@bel.co.in | I10: 04002775/002 | J10: SPP | K10: Yes | L10: KRIND/W/SPP/AB240026 | M10: 45329 | N10: 1197980 | O10: January | P10: July | Q10: 1 | R10: 4000513646 | S10: 45832 | T10: 1406141 | U10: June | V10: 0 | Z10: yes | AB10: August | AC10: =SUMIF($O$8:$O$426,"August",$N$8:$N$426) -> 5170000 | AD10: =SUMIF($U$8:$U$426,"August",$T$8:$T$426) -> 2953103 | AE10: =SUMIF($P$8:$P$431,"August",$N$8:$N$431) -> 4745016 | AF10: =AE10-AD10 -> 1791913
A11: 4 | B11: 45666 | C11: Sulzer Pumps India Pvt Ltd | D11: Mumbai | E11: store | F11: Anant Tarniker | G11: 9833345459 | H11: anant.ternikar@sulzer.com | I11: 102006834 | J11: SPP | K11: Yes | L11: KRIND/W/SPP/AB24032 | M11: 45516 | N11: 643950 | O11: January | P11: December | Q11: 0.4 | V11: =Table626893456[[#This Row],[Offer Value]]-Table626893456[[#This Row],[PO Value]] -> 643950 | X11: discussion happened | Z11: Yes | AB11: September | AC11: =SUMIF($O$8:$O$426,"September",$N$8:$N$426) -> 4142775 | AD11: =SUMIF($U$8:$U$426,"September",$T$8:$T$426) -> 1750522 | AE11: =SUMIF($P$8:$P$431,"September",$N$8:$N$431) -> 1273000 | AF11: =AE11-AD11 -> -477522
A12: 5 | B12: 45666 | C12: Seco Tools India PVT LTD | D12: Pune | E12: Document Store | F12: Prasanna Godbole | G12: 7774083585 | H12: prasanna.godbole@secotools.com | I12: 16008208/001 | J12: Contract | K12: No | L12: KXIND/W/MC/AB24030 | M12: 45511 | N12: 62000 | O12: January | P12: February | Q12: 1 | R12: 10082197 | S12: 45636 | T12: 55000 | U12: January | V12: =Table626893456[[#This Row],[Offer Value]]-Table626893456[[#This Row],[PO Value]] -> 7000 | AB12: October | AC12: =SUMIF($O$8:$O$426,"October",$N$8:$N$426) -> 4747151 | AD12: =SUMIF($U$8:$U$426,"October",$T$8:$T$426) -> 2616357 | AE12: =SUMIF($P$8:$P$431,"October",$N$8:$N$431) -> 2694185 | AF12: =AE12-AD12 -> 77828
A13: 5 | C13: Seco Tools India PVT LTD | D13: Pune | E13: DTA | F13: Prasanna Godbole | G13: 7774083585 | H13: prasanna.godbole@secotools.com | I13: 16007507/001 | J13: Contract | K13: No | L13: KXIND/W/MC/AB24030 | M13: 45511 | N13: 62000 | O13: January | P13: February | Q13: 1 | R13: 10082196 | S13: 45636 | T13: 55000 | U13: January | V13: =Table626893456[[#This Row],[Offer Value]]-Table626893456[[#This Row],[PO Value]] -> 7000 | AB13: November | AC13: =SUMIF($O$8:$O$426,"November",$N$8:$N$426) -> 1326760 | AD13: =SUMIF($U$8:$U$426,"November",$T$8:$T$426) -> 3568228 | AE13: =SUMIF($P$8:$P$431,"November",$N$8:$N$431) -> 8781521 | AF13: =AE13-AD13 -> 5213293
A14: 5 | C14: Seco Tools India PVT LTD | D14: Pune | E14: Tool Room | F14: Prasanna Godbole | G14: 7774083585 | H14: prasanna.godbole@secotools.com | I14: 11010676/001 | J14: Contract | K14: No | L14: KXIND/W/MC/AB24030 | M14: 45511 | N14: 62000 | O14: January | P14: February | Q14: 1 | R14: 10082196 | S14: 45636 | T14: 55000 | U14: January | V14: =Table626893456[[#This Row],[Offer Value]]-Table626893456[[#This Row],[PO Value]] -> 7000 | AB14: December | AC14: =SUMIF($O$8:$O$426,"December",$N$8:$N$426) -> 1046509 | AD14: =SUMIF($U$8:$U$426,"December",$T$8:$T$426) -> 573108 | AE14: =SUMIF($P$8:$P$431,"December",$N$8:$N$431) -> 8634215 | AF14: =AE14-AD14 -> 8061107
A15: 6 | B15: 45666 | C15: Sandvik Coromant India Pvt Ltd | D15: Pune | E15: Soft Tools | F15: Vivek Khodade | G15: 9823332725 | H15: vivek.khodade@sandvik.com | I15: 21003645/001 | J15: Relocation | K15: NO | L15: KRIND/W/RF/AB24048 | M15: 45610 | N15: 560000 | O15: January | P15: June | Q15: 1 | R15: 4512705805 | S15: 45814 | T15: 520000 | U15: June | V15: 0
A16: 7 | B16: 45666 | C16: Seco Tools India PVT LTD | D16: Pune | E16: IGS | F16: Arun kadam | G16: 9552579436 | H16: Arun.Kadam@secotools.com | I16: 13005433/001 | J16: Contract | K16: No | L16: KXIND/W/MC/AB24036 | M16: 45609 | N16: 62000 | O16: January | P16: May | Q16: 1 | R16: 10083149 | S16: 45650 | T16: 55000 | U16: January
A17: 7 | C17: Seco Tools India PVT LTD | D17: Pune | E17: Press shop | F17: Arun kadam | G17: 9552579436 | H17: Arun.Kadam@secotools.com | I17: 11010646/001 | J17: Contract | K17: No | L17: KXIND/W/MC/AB24036 | M17: 45609 | N17: 62000 | O17: January | P17: January | Q17: 1 | R17: 10083157 | S17: 45650 | T17: 55000 | U17: January | V17: 0
A18: 7 | C18: Seco Tools India PVT LTD | D18: Pune | E18: Sinter | F18: Arun kadam | G18: 9552579436 | H18: Arun.Kadam@secotools.com | I18: 13001978/001 | J18: Contract | K18: No | L18: KXIND/W/MC/AB24036 | M18: 45609 | N18: 62000 | O18: January | P18: January | Q18: 1 | R18: 10083150 | S18: 45650 | T18: 55000 | U18: January | V18: 0
A19: 8 | B19: 45666 | C19: Bharat Forge LTD | D19: Pune | E19: Aerospace | F19: Kiran Patil | G19: 9881340014 | H19: Kiran.Patil@bharatforge.com | I19: 17007143/001 | J19: Contract | K19: No | L19: KXIND/W/MC/AB/24038 | M19: 45610 | N19: 85000 | O19: January | P19: May | Q19: 1 | R19: 4601450532 | S19: 45796 | T19: 75000 | U19: May | V19: 0
A20: 9 | B20: 45666 | C20: Cummins India Ltd | D20: Pune | E20: KV & NHNT | F20: Vishal B Kalshetti | G20: 8888869627 | H20: Vishal.Kalshetti@cummins.com | I20: 07002616/001 | J20: Contract | K20: No | L20: KRIND/W/MC/AB/240039 | M20: 45610 | N20: 80000 | O20: January | P20: January | Q20: 1 | R20: IND7985383 | S20: 45663 | T20: 80000 | U20: January | V20: =Table626893456[[#This Row],[Offer Value]]-Table626893456[[#This Row],[PO Value]] -> 0 | W20: Please share the PO copy
A21: 9 | C21: Cummins India Ltd | D21: Pune | E21: KV & NHNT | F21: Vishal B Kalshetti | G21: 8888869627 | H21: Vishal.Kalshetti@cummins.com | I21: 00009908/002 | J21: Contract | K21: No | L21: KRIND/W/MC/AB/240039 | M21: 45610 | N21: 80000 | O21: January | P21: January | Q21: 1 | R21: IND7985383 | S21: 45663 | T21: 80000 | U21: January | V21: =Table626893456[[#This Row],[Offer Value]]-Table626893456[[#This Row],[PO Value]] -> 0
A22: 9 | C22: Cummins India Ltd | D22: Pune | E22: KV & NHNT | F22: Vishal B Kalshetti | G22: 8888869627 | H22: Vishal.Kalshetti@cummins.com | I22: 00009908/003 | J22: Contract | K22: No | L22: KRIND/W/MC/AB/240039 | M22: 45610 | N22: 80000 | O22: January | P22: January | Q22: 1 | R22: IND7985383 | S22: 45663 | T22: 80000 | U22: January | V22: =Table626893456[[#This Row],[Offer Value]]-Table626893456[[#This Row],[PO Value]] -> 0
A23: 9 | C23: Cummins India Ltd | D23: Pune | E23: KV & NHNT | F23: Vishal B Kalshetti | G23: 8888869627 | H23: Vishal.Kalshetti@cummins.com | I23: 00009908/004 | J23: Contract | K23: No | L23: KRIND/W/MC/AB/240039 | M23: 45610 | N23: 80000 | O23: January | P23: January | Q23: 1 | R23: IND7985383 | S23: 45663 | T23: 80000 | U23: January | V23: =Table626893456[[#This Row],[Offer Value]]-Table626893456[[#This Row],[PO Value]] -> 0
A24: 9 | C24: Cummins India Ltd | D24: Pune | E24: KV & NHNT | F24: Vishal B Kalshetti | G24: 8888869627 | H24: Vishal.Kalshetti@cummins.com | I24: 00009908/005 | J24: Contract | K24: No | L24: KRIND/W/MC/AB/240039 | M24: 45610 | N24: 80000 | O24: January | P24: January | Q24: 1 | R24: IND7985383 | S24: 45663 | T24: 80000 | U24: January | V24: =Table626893456[[#This Row],[Offer Value]]-Table626893456[[#This Row],[PO Value]] -> 0
A25: 9 | C25: Cummins India Ltd | D25: Pune | E25: KV & NHNT | F25: Vishal B Kalshetti | G25: 8888869627 | H25: Vishal.Kalshetti@cummins.com | I25: 01000708/001 | J25: Contract | K25: No | L25: KRIND/W/MC/AB/240039 | M25: 45610 | N25: 80000 | O25: January | P25: January | Q25: 1 | R25: IND7985383 | S25: 45663 | T25: 80000 | U25: January | V25: =Table626893456[[#This Row],[Offer Value]]-Table626893456[[#This Row],[PO Value]] -> 0
A26: 9 | C26: Cummins India Ltd | D26: Pune | E26: KV & NHNT | F26: Vishal B Kalshetti | G26: 8888869627 | H26: Vishal.Kalshetti@cummins.com | I26: 00009908/001 | J26: Contract | K26: No | L26: KRIND/W/MC/AB/240039 | M26: 45610 | N26: 80000 | O26: January | P26: January | Q26: 1 | R26: IND7985383 | S26: 45663 | T26: 80000 | U26: January | V26: =Table626893456[[#This Row],[Offer Value]]-Table626893456[[#This Row],[PO Value]] -> 0
A27: 10 | B27: 45666 | C27: Alfa Laval India LTD | D27: Pune | E27: Decanter | F27: Sagar Pawar | G27: 7798824040 | H27: Sagar.Pawar@alfalaval.com | I27: 05004742/001 | J27: Contract | K27: No | L27: KXIND/W/MC/AB24040 | M27: 45610 | N27: 77500 | O27: January | P27: February | Q27: 1 | R27: 8172731 | S27: 45700 | T27: 77500 | U27: February | V27: =Table626893456[[#This Row],[Offer Value]]-Table626893456[[#This Row],[PO Value]] -> 0
A28: 10 | C28: Alfa Laval India LTD | D28: Pune | E28: Decanter | F28: Sagar Pawar | G28: 7798824040 | H28: Sagar.Pawar@alfalaval.com | I28: 07005169/001 | J28: Contract | K28: No | L28: KXIND/W/MC/AB24040 | M28: 45610 | N28: 77500 | O28: January | P28: February | Q28: 1 | R28: 8172731 | S28: 45700 | T28: 77500 | U28: February | V28: =Table626893456[[#This Row],[Offer Value]]-Table626893456[[#This Row],[PO Value]] -> 0
A29: 10 | C29: Alfa Laval India LTD | D29: Pune | E29: Decanter | F29: Sagar Pawar | G29: 7798824040 | H29: Sagar.Pawar@alfalaval.com | I29: 07005164/001 | J29: Contract | K29: No | L29: KXIND/W/MC/AB24040 | M29: 45610 | N29: 77500 | O29: January | P29: February | Q29: 1 | R29: 8172731 | S29: 45700 | T29: 77500 | U29: February | V29: =Table626893456[[#This Row],[Offer Value]]-Table626893456[[#This Row],[PO Value]] -> 0
A30: 10 | C30: Alfa Laval India LTD | D30: Pune | E30: Decanter | F30: Sagar Pawar | G30: 7798824040 | H30: Sagar.Pawar@alfalaval.com | I30: 10010116/001 | J30: Contract | K30: No | L30: KXIND/W/MC/AB24040 | M30: 45610 | N30: 77500 | O30: January | P30: February | Q30: 1 | R30: 8172731 | S30: 45700 | T30: 77500 | U30: February | V30: =Table626893456[[#This Row],[Offer Value]]-Table626893456[[#This Row],[PO Value]] -> 0
A31: 11 | B31: 45666 | C31: Alfa Laval India LTD | D31: Pune | E31: DLC | F31: Ranjit Shinde | G31: 7045525011 | H31: ranjit.shinde@alfalaval.com | I31: 07010871/001 | J31: Contract | K31: No | L31: KXIND/W/MC/AB24041 | M31: 45610 | N31: 77500 | O31: January | P31: February | Q31: 1 | R31: 8172511 | S31: 45693 | T31: 77500 | U31: February | V31: =Table626893456[[#This Row],[Offer Value]]-Table626893456[[#This Row],[PO Value]] -> 0
A32: 11 | C32: Alfa Laval India LTD | D32: Pune | E32: DLC | F32: Ranjit Shinde | G32: 7045525011 | H32: ranjit.shinde@alfalaval.com | I32: 19008264/001 | J32: Contract | K32: No | L32: KXIND/W/MC/AB24041 | M32: 45610 | N32: 77500 | O32: January | P32: February | Q32: 1 | R32: 8172511 | S32: 45693 | T32: 77500 | U32: February | V32: =Table626893456[[#This Row],[Offer Value]]-Table626893456[[#This Row],[PO Value]] -> 0
A33: 11 | C33: Alfa Laval India LTD | D33: Pune | E33: DLC | F33: Ranjit Shinde | G33: 7045525011 | H33: ranjit.shinde@alfalaval.com | I33: 22008500/001 | J33: Contract | K33: yes | L33: KXIND/W/MC/AB24041 | M33: 45610 | N33: 77500 | O33: January | P33: February | Q33: 1 | R33: 8172511 | S33: 45693 | T33: 77500 | U33: February | V33: =Table626893456[[#This Row],[Offer Value]]-Table626893456[[#This Row],[PO Value]] -> 0
A34: 12 | B34: 45666 | C34: Alfa Laval India LTD | D34: Pune | E34: Stores | F34: Jitu Shirke | G34: 9623003468 | H34: jitendra.shirke@alfalaval.com | I34: 07008042/001 | J34: Contract | K34: No | L34: KXIND/W/MC/AB24042 | M34: 45618 | N34: 77500 | O34: January | P34: January | Q34: 1 | R34: 8171479 | S34: 45663 | T34: 77500 | U34: January | V34: =Table626893456[[#This Row],[Offer Value]]-Table626893456[[#This Row],[PO Value]] -> 0
A35: 12 | C35: Alfa Laval India LTD | D35: Pune | E35: Stores | F35: Jitu Shirke | G35: 9623003468 | H35: jitendra.shirke@alfalaval.com | I35: 1100003/001 | J35: Contract | K35: No | L35: KXIND/W/MC/AB24042 | M35: 45618 | N35: 77500 | O35: January | P35: January | Q35: 1 | R35: 8171479 | S35: 45663 | T35: 77500 | U35: January | V35: =Table626893456[[#This Row],[Offer Value]]-Table626893456[[#This Row],[PO Value]] -> 0
A36: 12 | C36: Alfa Laval India LTD | D36: Pune | E36: Stores | F36: Jitu Shirke | G36: 9623003468 | H36: jitendra.shirke@alfalaval.com | I36: 22006265/001 | J36: Contract | K36: YES | L36: KXIND/W/MC/AB24042 | M36: 45618 | N36: 77500 | O36: January | P36: January | Q36: 1 | R36: 8171479 | S36: 45663 | T36: 77500 | U36: January | V36: =Table626893456[[#This Row],[Offer Value]]-Table626893456[[#This Row],[PO Value]] -> 0
A37: 13 | B37: 45666 | C37: Bharat Forge LTD | D37: Pune | E37: Aerospace | F37: Kiran Patil | G37: 9881340014 | H37: Kiran.Patil@bharatforge.com | I37: 17007143/001 | J37: Relocation | K37: No | L37: KAR/IND/RE/AB/007 | M37: 45580 | N37: 350000 | O37: January | P37: December | Q37: 0.5 | V37: =Table626893456[[#This Row],[Offer Value]]-Table626893456[[#This Row],[PO Value]] -> 350000
A38: 14 | B38: 45666 | C38: Siemens Ltd. | D38: Pune | E38: Switchboard | F38: Amar Gurav | G38: 8879112999 | H38: amar.gurav@siemens.com | I38: 09002885/001 | J38: Relocation | K38: No | L38: KAR/IND/RE/AB/008 | M38: 45614 | N38: 395000 | O38: January | P38: January | Q38: 1 | R38: 4513271995 | S38: 45664 | T38: 390000 | U38: January | V38: =Table626893456[[#This Row],[Offer Value]]-Table626893456[[#This Row],[PO Value]] -> 5000 | Y38: 45901
A39: 15 | B39: 45666 | C39: Seco Tools India PVT LTD | D39: Pune | E39: Final Ins | F39: Arun kadam | G39: 9552579436 | H39: Arun.Kadam@secotools.com | I39: 22005009/001 | J39: Contract | K39: Yes | L39: KXIND/W/MC/AB24046 | M39: 45645 | N39: 55000 | O39: January | P39: January | Q39: 1 | R39: 10083147 | S39: 24/12/2025 | T39: 55000 | U39: January | V39: =Table626893456[[#This Row],[Offer Value]]-Table626893456[[#This Row],[PO Value]] -> 0
A40: 16 | B40: 45666 | C40: Sandvik Coromant India Pvt Ltd | D40: pune | E40: Lapping | F40: Mahesh Ambawale | G40: 9881379339 | H40: mahesh.ambawale@sandvik.com | I40: 17008268/001 | J40: SPP | K40: Yes | L40: KRIND/W/SPP/AB24049 | M40: 45654 | N40: 156091 | O40: January | P40: January | Q40: 1 | R40: 4512110539 | S40: 20/01/2025 | T40: 151408 | U40: January | V40: =Table626893456[[#This Row],[Offer Value]]-Table626893456[[#This Row],[PO Value]] -> 4683 | Y40: 29/1/2025
A41: 17 | B41: 45666 | C41: Wirtgen India Pvt.Ltd. | D41: Pune | E41: Stores | F41: Sagar Brijpuriya | G41: 8956509715 | H41: sagar.brijpuriya@wirtgen-group.com | I41: 16004741/001 | J41: Contract | K41: NO | L41: KXIND/W/MC/AB/25001 | M41: 45663 | N41: 67000 | O41: January | P41: January | Q41: 1 | R41: 4504516357 | S41: 45712 | T41: 65000 | U41: February | V41: 0
...

Sheet Rahul
H1: 2062108 | AB1: Month wise data
A2: KARDEX INDIA - LIVE OFFER FUNEL - RAHUL - WEST | AB2: Month | AC2: Offers Total | AD2: Order received | AE2: Forecast | AF2: Forecast- Po Received
U3: Total Offered Value | V3: =SUM(N7:N397) -> 56159754 | AB3: January | AC3: =SUMIF($O$7:$O$397,"January",$N$7:$N$397) -> 18381668 | AD3: =SUMIF($U$7:$U$397,"January",$T$7:$T$397) -> 5747102 | AE3: =SUMIF($P$7:$P$427,"January",$N$7:$N$427) -> 6160514 | AF3: =AE3-AD3 -> 413412
A4: Total Offers | B4: =COUNTA(B7:B1419) -> 208 | U4: Order Received | V4: =SUM(T7:T397) -> 30514486 | AB4: February | AC4: =SUMIF($O$7:$O$397,"February",$N$7:$N$397) -> 6168252 | AD4: =SUMIF($U$7:$U$397,"February",$T$7:$T$397) -> 539332 | AE4: =SUMIF($P$7:$P$427,"February",$N$7:$N$427) -> 4146986 | AF4: =AE4-AD4 -> 3607654
